Workbook

Sheet Research Summary
A1: Pune & Mumbai MMR - MahaRERA Developers and Projects Database
A2: PARTIAL DATASET - NOT A COMPLETE LIST OF PUNE AND MUMBAI/MMR PROJECTS | C2: Only part of the official registered-project listing could be collected within MahaRERA's rate limits. See "Coverage & Missing Pages".
A3: Workbook generated | B3: 2026-10-11 06:39:08 UTC
A4: Data collection date(s) | B4: 2026-10-11 | C4: Dates the official pages were retrieved
A5: Source | B5: MahaRERA | C5: Maharashtra Real Estate Regulatory Authority, https://maharera.maharashtra.gov.in - reproduced under its copyright policy
A7: Collected records
A8: Unique MahaRERA project registrations collected | B8: =COUNTA('Registered Projects'!B2:B1571) -> 1570 | C8: Deduplicated on registration number
A9: Unique developers / promoters (from collected projects) | B9: =COUNTA('Developer Directory'!A2:A1189) -> 1188 | C9: Exact promoter name after case/whitespace/punctuation normalisation; no fuzzy merging
A10: Pune projects | B10: =COUNTIF('Registered Projects'!J2:J1571,"Pune") -> 260 | C10: District = Pune. Portal total: 12996
A11: Mumbai MMR projects | B11: =COUNTIF('Registered Projects'!J2:J1571,"Mumbai MMR") -> 1310 | C11: Mumbai City, Mumbai Suburban, Thane, Raigad, Palghar
A12: of which Mumbai City | B12: =COUNTIF('Registered Projects'!I2:I1571,"Mumbai City") -> 640 | C12: Portal total: 1299; collected 64/130 pages
A13: of which Mumbai Suburban | B13: =COUNTIF('Registered Projects'!I2:I1571,"Mumbai Suburban") -> 190 | C13: Portal total: 6324; collected 19/633 pages
A14: of which Thane | B14: =COUNTIF('Registered Projects'!I2:I1571,"Thane") -> 470 | C14: Portal total: 6988; collected 47/699 pages
A15: of which Raigad (shown as "Raigarh" by MahaRERA) | B15: =COUNTIF('Registered Projects'!I2:I1571,"Raigarh") -> 10 | C15: Portal total: 5416; collected 1/542 pages
A16: of which Palghar | B16: =COUNTIF('Registered Projects'!I2:I1571,"Palghar") -> 0 | C16: Portal total: 2706; collected 0/271 pages
A18: Record verification (Registered Projects)
A19: Verified (official listing) | B19: =COUNTIF('Registered Projects'!Y2:Y1571,"Verified (official listing)") -> 1544 | C19: All listing fields present and consistent
A20: Partially verified | B20: =COUNTIF('Registered Projects'!Y2:Y1571,"Partially verified") -> 26 | C20: Some listing field blank or inconsistent
A21: Unverified records included | B21: 0 | C21: None. Records from throttled/ambiguous pages were not created; those pages are listed as missing.
A22: Pages throttled / unverified (not collected) | B22: =SUM('Coverage & Missing Pages'!F2:F9)-'Coverage & Missing Pages'!F9 -> 4 | C22: Across all search categories
A23: Note | C23: All records lack project address, registration date and original completion date (detail pages not collected). Status for every record is cross-checked against official lists, but the Revoked search itself is only partly collected.
A25: Status (Registered Projects sheet - one status per project)
A26: Registered - no adverse list match | B26: =COUNTIF('Registered Projects'!Q2:Q1571,"Registered - no adverse list match") -> 1557
A27: Revoked | B27: =COUNTIF('Registered Projects'!Q2:Q1571,"Revoked") -> 0
A28: Deregistered | B28: =COUNTIF('Registered Projects'!Q2:Q1571,"Deregistered") -> 6
A29: Abeyance - lapse of completion date | B29: =COUNTIF('Registered Projects'!Q2:Q1571,"Abeyance - lapse of completion date") -> 1
A30: Abeyance - QPR non-compliance | B30: =COUNTIF('Registered Projects'!Q2:Q1571,"Abeyance - QPR non-compliance") -> 5
A31: Abeyance - common bank account | B31: =COUNTIF('Registered Projects'!Q2:Q1571,"Abeyance - common bank account") -> 1
A32: Extension certificate shown | B32: =COUNTIF('Registered Projects'!R2:R1571,"Yes") -> 696 | C32: Extension Certificate link present on listing card
A34: Status lists (Revoked Dereg Lapsed Projects sheet - all in-scope districts, one row per project)
A35: Projects on any status list | B35: =COUNTA('Revoked Dereg Lapsed Projects'!A2:A4378) -> 4377 | C35: Official lists were downloaded in full, so this covers all 6 districts
A36: Revoked = Yes | B36: =COUNTIF('Revoked Dereg Lapsed Projects'!G2:G4378,"Yes") -> 40 | C36: Under-reported: Revoked search only partly collected
A37: Deregistered = Yes | B37: =COUNTIF('Revoked Dereg Lapsed Projects'!H2:H4378,"Yes") -> 355 | C37: Separate column per list; a project on two lists is counted once in the total above
A38: Abeyance - Lapse of Completion Date = Yes | B38: =COUNTIF('Revoked Dereg Lapsed Projects'!I2:I4378,"Yes") -> 2773 | C38: Separate column per list; a project on two lists is counted once in the total above
A39: Abeyance - QPR Non-compliance = Yes | B39: =COUNTIF('Revoked Dereg Lapsed Projects'!J2:J4378,"Yes") -> 874 | C39: Separate column per list; a project on two lists is counted once in the total above
A40: Abeyance - Common Bank Account = Yes | B40: =COUNTIF('Revoked Dereg Lapsed Projects'!K2:K4378,"Yes") -> 133 | C40: Separate column per list; a project on two lists is counted once in the total above
A41: NCLT Listed = Yes | B41: =COUNTIF('Revoked Dereg Lapsed Projects'!L2:L4378,"Yes") -> 316 | C41: Separate column per list; a project on two lists is counted once in the total above
A42: Not present in collected registered pages | B42: =COUNTIF('Revoked Dereg Lapsed Projects'!O2:O4378,"No") -> 4351 | C42: Mostly because those districts are only partly collected
A44: Missing fields (Registered Projects)
A45: Project Address blank | B45: =COUNTBLANK('Registered Projects'!F2:F1571) -> 1570 | C45: Left blank - not verified
...

Sheet Developer Directory
A1: Developer ID | B1: Developer / Promoter Legal Name (as displayed on MahaRERA) | C1: Name Variants Seen | D1: Brand / Trading Name | E1: Company Type | F1: Official Website | G1: Public Business Address | H1: Districts of Registered Projects | I1: Official Business Contact | J1: Registered Projects Collected (count) | K1: Pune Projects (count) | L1: Mumbai MMR Projects (count) | M1: Projects with Adverse Flag (count) | N1: MahaRERA Registration Nos. (collected) | O1: Source URL | P1: Retrieved Date | Q1: Verification Status
A2: D00001 | B2: A G SUPERSTRUCTURES PVT LTD | E2: Private Limited Company (from name suffix) | H2: Thane | J2: 1 | K2: 0 | L2: 1 | M2: 0 | N2: P51700001636 | O2: https://www.maharera.maharashtra.gov.in/projects-search-result?project_state=27&project_district=517&page=1 | P2: 2026-10-11 | Q2: Partially verified: legal name and registration nos. verified on MahaRERA listing. Brand, website, address, contact NOT collected. Company type derived from name suffix only. Project count reflects collected pages only.
A3: D00002 | B3: A. P. BHANDARI DEVELOPERS | H3: Pune | J3: 1 | K3: 1 | L3: 0 | M3: 0 | N3: P52100001730 | O3: https://www.maharera.maharashtra.gov.in/projects-search-result?project_state=27&project_district=521&page=4 | P3: 2026-10-11 | Q3: Partially verified: legal name and registration nos. verified on MahaRERA listing. Brand, website, address, contact NOT collected. Company type derived from name suffix only. Project count reflects collected pages only.
A4: D00003 | B4: A.PATNI REALTY PRIVATE LIMITED | E4: Private Limited Company (from name suffix) | H4: Mumbai City | J4: 1 | K4: 0 | L4: 1 | M4: 0 | N4: P51900010462 | O4: https://www.maharera.maharashtra.gov.in/projects-search-result?project_state=27&project_district=519&page=43 | P4: 2026-10-11 | Q4: Partially verified: legal name and registration nos. verified on MahaRERA listing. Brand, website, address, contact NOT collected. Company type derived from name suffix only. Project count reflects collected pages only.
A5: D00004 | B5: A PLUS REALTY | H5: Thane | J5: 1 | K5: 0 | L5: 1 | M5: 0 | N5: P51700002661 | O5: https://www.maharera.maharashtra.gov.in/projects-search-result?project_state=27&project_district=517&page=15 | P5: 2026-10-11 | Q5: Partially verified: legal name and registration nos. verified on MahaRERA listing. Brand, website, address, contact NOT collected. Company type derived from name suffix only. Project count reflects collected pages only.
A6: D00005 | B6: A.R ASSOCIATES | H6: Mumbai City | J6: 1 | K6: 0 | L6: 1 | M6: 0 | N6: P51900007503 | O6: https://www.maharera.maharashtra.gov.in/projects-search-result?project_state=27&project_district=519&page=25 | P6: 2026-10-11 | Q6: Partially verified: legal name and registration nos. verified on MahaRERA listing. Brand, website, address, contact NOT collected. Company type derived from name suffix only. Project count reflects collected pages only.
A7: D00006 | B7: A R Constructions | H7: Mumbai City | J7: 1 | K7: 0 | L7: 1 | M7: 0 | N7: P51900000604 | O7: https://www.maharera.maharashtra.gov.in/projects-search-result?project_state=27&project_district=519&page=5 | P7: 2026-10-11 | Q7: Partially verified: legal name and registration nos. verified on MahaRERA listing. Brand, website, address, contact NOT collected. Company type derived from name suffix only. Project count reflects collected pages only.
A8: D00007 | B8: A V ASSOCIATES | H8: Thane | J8: 1 | K8: 0 | L8: 1 | M8: 0 | N8: P51700001018 | O8: https://www.maharera.maharashtra.gov.in/projects-search-result?project_state=27&project_district=517&page=8 | P8: 2026-10-11 | Q8: Partially verified: legal name and registration nos. verified on MahaRERA listing. Brand, website, address, contact NOT collected. Company type derived from name suffix only. Project count reflects collected pages only.
A9: D00008 | B9: AADI DEVELOPERS | H9: Thane | J9: 1 | K9: 0 | L9: 1 | M9: 0 | N9: P51700003336 | O9: https://www.maharera.maharashtra.gov.in/projects-search-result?project_state=27&project_district=517&page=16 | P9: 2026-10-11 | Q9: Partially verified: legal name and registration nos. verified on MahaRERA listing. Brand, website, address, contact NOT collected. Company type derived from name suffix only. Project count reflects collected pages only.
A10: D00009 | B10: Aadinath builders & developers | H10: Thane | J10: 1 | K10: 0 | L10: 1 | M10: 0 | N10: P51700005002 | O10: https://www.maharera.maharashtra.gov.in/projects-search-result?project_state=27&project_district=517&page=31 | P10: 2026-10-11 | Q10: Partially verified: legal name and registration nos. verified on MahaRERA listing. Brand, website, address, contact NOT collected. Company type derived from name suffix only. Project count reflects collected pages only.
A11: D00010 | B11: Aakaar Tanishq Nirmaan J. V. | H11: Mumbai City | J11: 1 | K11: 0 | L11: 1 | M11: 0 | N11: P51900006567 | O11: https://www.maharera.maharashtra.gov.in/projects-search-result?project_state=27&project_district=519&page=34 | P11: 2026-10-11 | Q11: Partially verified: legal name and registration nos. verified on MahaRERA listing. Brand, website, address, contact NOT collected. Company type derived from name suffix only. Project count reflects collected pages only.
A12: D00011 | B12: AAKASH ASSOCIATES INFRASTRUCTURE | H12: Mumbai City | J12: 1 | K12: 0 | L12: 1 | M12: 1 | N12: P51900012769 | O12: https://www.maharera.maharashtra.gov.in/projects-search-result?project_state=27&project_district=519&page=52 | P12: 2026-10-11 | Q12: Partially verified: legal name and registration nos. verified on MahaRERA listing. Brand, website, address, contact NOT collected. Company type derived from name suffix only. Project count reflects collected pages only.
A13: D00012 | B13: AAKASH BUILDERS & DEVELOPERS | H13: Thane | J13: 1 | K13: 0 | L13: 1 | M13: 0 | N13: P51700011846 | O13: https://www.maharera.maharashtra.gov.in/projects-search-result?project_state=27&project_district=517&page=29 | P13: 2026-10-11 | Q13: Partially verified: legal name and registration nos. verified on MahaRERA listing. Brand, website, address, contact NOT collected. Company type derived from name suffix only. Project count reflects collected pages only.
A14: D00013 | B14: AALAY DEVELOPERS | H14: Mumbai City | J14: 1 | K14: 0 | L14: 1 | M14: 0 | N14: P51900004114 | O14: https://www.maharera.maharashtra.gov.in/projects-search-result?project_state=27&project_district=519&page=13 | P14: 2026-10-11 | Q14: Partially verified: legal name and registration nos. verified on MahaRERA listing. Brand, website, address, contact NOT collected. Company type derived from name suffix only. Project count reflects collected pages only.
A15: D00014 | B15: AAMANTRAN DEVELOPERS | H15: Thane | J15: 1 | K15: 0 | L15: 1 | M15: 0 | N15: P51700003251 | O15: https://www.maharera.maharashtra.gov.in/projects-search-result?project_state=27&project_district=517&page=35 | P15: 2026-10-11 | Q15: Partially verified: legal name and registration nos. verified on MahaRERA listing. Brand, website, address, contact NOT collected. Company type derived from name suffix only. Project count reflects collected pages only.
A16: D00015 | B16: AANANDVARDHAN REALTORS | H16: Mumbai City | J16: 1 | K16: 0 | L16: 1 | M16: 0 | N16: P51900011546 | O16: https://www.maharera.maharashtra.gov.in/projects-search-result?project_state=27&project_district=519&page=48 | P16: 2026-10-11 | Q16: Partially verified: legal name and registration nos. verified on MahaRERA listing. Brand, website, address, contact NOT collected. Company type derived from name suffix only. Project count reflects collected pages only.
... A24: D00023 | B24: Abhimanyu Group | H24: Pune | J24: 1 | K24: 1 | L24: 0 | M24: 0 | N24: P52100010222 | O24: https://www.maharera.maharashtra.gov.in/projects-search-result?project_state=27&project_district=521&page=23 | P24: 2026-10-11 | Q24: Partially verified: legal name and registration nos. verified on MahaRERA listing. Brand, website, address, contact NOT collected. Company type derived from name suffix only. Project count reflects collected pages only.
A25: D00024 | B25: ACCORD ESTATES PVT LTD | E25: Private Limited Company (from name suffix) | H25: Mumbai City | J25: 1 | K25: 0 | L25: 1 | M25: 0 | N25: P51900006752 | O25: https://www.maharera.maharashtra.gov.in/projects-search-result?project_state=27&project_district=519&page=33 | P25: 2026-10-11 | Q25: Partially verified: legal name and registration nos. verified on MahaRERA listing. Brand, website, address, contact NOT collected. Company type derived from name suffix only. Project count reflects collected pages only.
A26: D00025 | B26: ACE AURUM | H26: Pune | J26: 1 | K26: 1 | L26: 0 | M26: 0 | N26: P52100000090 | O26: https://www.maharera.maharashtra.gov.in/projects-search-result?project_state=27&project_district=521&page=4 | P26: 2026-10-11 | Q26: Partially verified: legal name and registration nos. verified on MahaRERA listing. Brand, website, address, contact NOT collected. Company type derived from name suffix only. Project count reflects collected pages only.
A27: D00026 | B27: ACEAUGUSTA | H27: Pune | J27: 1 | K27: 1 | L27: 0 | M27: 0 | N27: P52100000080 | O27: https://www.maharera.maharashtra.gov.in/projects-search-result?project_state=27&project_district=521&page=6 | P27: 2026-10-11 | Q27: Partially verified: legal name and registration nos. verified on MahaRERA listing. Brand, website, address, contact NOT collected. Company type derived from name suffix only. Project count reflects collected pages only.
A28: D00027 | B28: Acme Housing India Private Limited | E28: Private Limited Company (from name suffix) | H28: Thane | J28: 4 | K28: 0 | L28: 4 | M28: 0 | N28: P51700000778, P51700001032, P51700001033, P51700001038 | O28: https://www.maharera.maharashtra.gov.in/projects-search-result?project_state=27&project_district=517&page=23 | P28: 2026-10-11 | Q28: Partially verified: legal name and registration nos. verified on MahaRERA listing. Brand, website, address, contact NOT collected. Company type derived from name suffix only. Project count reflects collected pages only.
A29: D00028 | B29: ACME SAWANT VENTURES | H29: Pune | J29: 1 | K29: 1 | L29: 0 | M29: 0 | N29: P52100004621 | O29: https://www.maharera.maharashtra.gov.in/projects-search-result?project_state=27&project_district=521&page=23 | P29: 2026-10-11 | Q29: Partially verified: legal name and registration nos. verified on MahaRERA listing. Brand, website, address, contact NOT collected. Company type derived from name suffix only. Project count reflects collected pages only.
A30: D00029 | B30: ADANI DEVELOPERS PRIVATE LIMITED | E30: Private Limited Company (from name suffix) | H30: Mumbai City | J30: 2 | K30: 0 | L30: 2 | M30: 0 | N30: P51900006101, P51900008813 | O30: https://www.maharera.maharashtra.gov.in/projects-search-result?project_state=27&project_district=519&page=24 | P30: 2026-10-11 | Q30: Partially verified: legal name and registration nos. verified on MahaRERA listing. Brand, website, address, contact NOT collected. Company type derived from name suffix only. Project count reflects collected pages only.
A31: D00030 | B31: ADCON INFRAPROJECTS PVT.LTD. | E31: Private Limited Company (from name suffix) | H31: Mumbai Suburban | J31: 1 | K31: 0 | L31: 1 | M31: 0 | N31: P51800012207 | O31: https://www.maharera.maharashtra.gov.in/projects-search-result?project_state=27&project_district=518&page=10 | P31: 2026-10-11 | Q31: Partially verified: legal name and registration nos. verified on MahaRERA listing. Brand, website, address, contact NOT collected. Company type derived from name suffix only. Project count reflects collected pages only.
A32: D00031 | B32: ADHYA PROPERTIES | H32: Pune | J32: 2 | K32: 2 | L32: 0 | M32: 0 | N32: P52100001122, P52100001891 | O32: https://www.maharera.maharashtra.gov.in/projects-search-result?project_state=27&project_district=521&page=19 | P32: 2026-10-11 | Q32: Partially verified: legal name and registration nos. verified on MahaRERA listing. Brand, website, address, contact NOT collected. Company type derived from name suffix only. Project count reflects collected pages only.
A33: D00032 | B33: ADINATH ENTERPRISE | H33: Mumbai Suburban | J33: 1 | K33: 0 | L33: 1 | M33: 0 | N33: P51800000010 | O33: https://www.maharera.maharashtra.gov.in/projects-search-result?project_state=27&project_district=518&page=2 | P33: 2026-10-11 | Q33: Partially verified: legal name and registration nos. verified on MahaRERA listing. Brand, website, address, contact NOT collected. Company type derived from name suffix only. Project count reflects collected pages only.
A34: D00033 | B34: Aditdev Builders LLP | E34: LLP (from name suffix) | H34: Mumbai City | J34: 1 | K34: 0 | L34: 1 | M34: 0 | N34: P51900007964 | O34: https://www.maharera.maharashtra.gov.in/projects-search-result?project_state=27&project_district=519&page=33 | P34: 2026-10-11 | Q34: Partially verified: legal name and registration nos. verified on MahaRERA listing. Brand, website, address, contact NOT collected. Company type derived from name suffix only. Project count reflects collected pages only.
A35: D00034 | B35: Aditi Construction | H35: Thane | J35: 1 | K35: 0 | L35: 1 | M35: 0 | N35: P51700000782 | O35: https://www.maharera.maharashtra.gov.in/projects-search-result?project_state=27&project_district=517&page=4 | P35: 2026-10-11 | Q35: Partially verified: legal name and registration nos. verified on MahaRERA listing. Brand, website, address, contact NOT collected. Company type derived from name suffix only. Project count reflects collected pages only.
A36: D00035 | B36: Aditya Associates | H36: Thane | J36: 1 | K36: 0 | L36: 1 | M36: 0 | N36: P51700002433 | O36: https://www.maharera.maharashtra.gov.in/projects-search-result?project_state=27&project_district=517&page=12 | P36: 2026-10-11 | Q36: Partially verified: legal name and registration nos. verified on MahaRERA listing. Brand, website, address, contact NOT collected. Company type derived from name suffix only. Project count reflects collected pages only.
A37: D00036 | B37: ADITYA SHAGUN DEVELOPERS | H37: Pune | J37: 1 | K37: 1 | L37: 0 | M37: 0 | N37: P52100002025 | O37: https://www.maharera.maharashtra.gov.in/projects-search-result?project_state=27&project_district=521&page=22 | P37: 2026-10-11 | Q37: Partially verified: legal name and registration nos. verified on MahaRERA listing. Brand, website, address, contact NOT collected. Company type derived from name suffix only. Project count reflects collected pages only.
A38: D00037 | B38: ADVENT DEVELOPERS PRIVATE LIMITED | E38: Private Limited Company (from name suffix) | H38: Mumbai Suburban | J38: 1 | K38: 0 | L38: 1 | M38: 0 | N38: P51800002649 | O38: https://www.maharera.maharashtra.gov.in/projects-search-result?project_state=27&project_district=518&page=14 | P38: 2026-10-11 | Q38: Partially verified: legal name and registration nos. verified on MahaRERA listing. Brand, website, address, contact NOT collected. Company type derived from name suffix only. Project count reflects collected pages only.
A39: D00038 | B39: Agile Real Estate Pvt. Ltd. | E39: Private Limited Company (from name suffix) | H39: Thane | J39: 13 | K39: 0 | L39: 13 | M39: 0 | N39: P51700000625, P51700000635, P51700000640, P51700000732, P51700000922, P51700000924, P51700000925, P51700000927, P51700001039, P51700001040, P51700001083, P51700001278, P51700001310 | O39: https://www.maharera.maharashtra.gov.in/projects-search-result?project_state=27&project_district=517&page=25 | P39: 2026-10-11 | Q39: Partially verified: legal name and registration nos. verified on MahaRERA listing. Brand, website, address, contact NOT collected. Company type derived from name suffix only. Project count reflects collected pages only.
A40: D00039 | B40: AIKYA REALTY PVT LTD | E40: Private Limited Company (from name suffix) | H40: Mumbai City | J40: 1 | K40: 0 | L40: 1 | M40: 0 | N40: P51900002496 | O40: https://www.maharera.maharashtra.gov.in/projects-search-result?project_state=27&project_district=519&page=6 | P40: 2026-10-11 | Q40: Partially verified: legal name and registration nos. verified on MahaRERA listing. Brand, website, address, contact NOT collected. Company type derived from name suffix only. Project count reflects collected pages only.
A41: D00040 | B41: AJAY MADHUKAR THANEKAR | H41: Thane | J41: 2 | K41: 0 | L41: 2 | M41: 0 | N41: P51700000644, P51700001024 | O41: https://www.maharera.maharashtra.gov.in/projects-search-result?project_state=27&project_district=517&page=1 | P41: 2026-10-11 | Q41: Partially verified: legal name and registration nos. verified on MahaRERA listing. Brand, website, address, contact NOT collected. Company type derived from name suffix only. Project count reflects collected pages only.
A42: D00041 | B42: AJIT ANANT BARVE | H42: Mumbai City | J42: 1 | K42: 0 | L42: 1 | M42: 0 | N42: P51900012656 | O42: https://www.maharera.maharashtra.gov.in/projects-search-result?project_state=27&project_district=519&page=37 | P42: 2026-10-11 | Q42: Partially verified: legal name and registration nos. verified on MahaRERA listing. Brand, website, address, contact NOT collected. Company type derived from name suffix only. Project count reflects collected pages only.
A43: D00042 | B43: AJIT KRISHNAN RATNAM | H43: Thane | J43: 1 | K43: 0 | L43: 1 | M43: 0 | N43: P51700003326 | O43: https://www.maharera.maharashtra.gov.in/projects-search-result?project_state=27&project_district=517&page=16 | P43: 2026-10-11 | Q43: Partially verified: legal name and registration nos. verified on MahaRERA listing. Brand, website, address, contact NOT collected. Company type derived from name suffix only. Project count reflects collected pages only.
A44: D00043 | B44: Akbar Mohamadali Kazi | H44: Mumbai City | J44: 1 | K44: 0 | L44: 1 | M44: 0 | N44: P51900006052 | O44: https://www.maharera.maharashtra.gov.in/projects-search-result?project_state=27&project_district=519&page=3 | P44: 2026-10-11 | Q44: Partially verified: legal name and registration nos. verified on MahaRERA listing. Brand, website, address, contact NOT collected. Company type derived from name suffix only. Project count reflects collected pages only.
A45: D00044 | B45: Akshay Enterprises | H45: Thane | J45: 1 | K45: 0 | L45: 1 | M45: 0 | N45: P51700002757 | O45: https://www.maharera.maharashtra.gov.in/projects-search-result?project_state=27&project_district=517&page=5 | P45: 2026-10-11 | Q45: Partially verified: legal name and registration nos. verified on MahaRERA listing. Brand, website, address, contact NOT collected. Company type derived from name suffix only. Project count reflects collected pages only.
A46: D00045 | B46: AKSHAY GRUHPRAVESH LLP | E46: LLP (from name suffix) | H46: Mumbai Suburban | J46: 1 | K46: 0 | L46: 1 | M46: 0 | N46: P51800000487 | O46: https://www.maharera.maharashtra.gov.in/projects-search-result?project_state=27&project_district=518&page=8 | P46: 2026-10-11 | Q46: Partially verified: legal name and registration nos. verified on MahaRERA listing. Brand, website, address, contact NOT collected. Company type derived from name suffix only. Project count reflects collected pages only.
A47: D00046 | B47: AL HAADI DEVELOPERS | H47: Mumbai City | J47: 1 | K47: 0 | L47: 1 | M47: 0 | N47: P51900011681 | O47: https://www.maharera.maharashtra.gov.in/projects-search-result?project_state=27&project_district=519&page=40 | P47: 2026-10-11 | Q47: Partially verified: legal name and registration nos. verified on MahaRERA listing. Brand, website, address, contact NOT collected. Company type derived from name suffix only. Project count reflects collected pages only.
...

Sheet Registered Projects
A1: Record ID | B1: MahaRERA Registration No. | C1: Project Name | D1: Promoter / Developer Name (as displayed) | E1: Developer ID | F1: Project Address | G1: Locality / Taluka (as displayed) | H1: Pincode | I1: District | J1: Region Group | K1: Sub-region | L1: Latitude | M1: Longitude | N1: Registration Date | O1: Original Completion Date | P1: Revised / Proposed Completion Date | Q1: Current Status (derived from official lists) | R1: Extension Certificate Shown | S1: Revocation / Lapse / Deregistration / Abeyance Indicated | T1: Status Flags Detail | U1: MahaRERA Last Modified | V1: Official Project Detail URL | W1: Source Listing URL | X1: Retrieved Date | Y1: Record Verification | Z1: Verified Fields | AA1: Missing / Unverified Fields | AB1: Status Verification | AC1: Notes
A2: R000001 | B2: P51700000001 | C2: MAYFAIR VISHWARAJA | D2: MAYFAIR HOUSING PRIVATE LIMITED | E2: D00568 | G2: Kalyan | H2: 421605 | I2: Thane | J2: Mumbai MMR | K2: Thane district (incl. Thane, Navi Mumbai-Thane side, Mira-Bhayandar, Kalyan-Dombivli, Bhiwandi, Ulhasnagar, Ambernath) | L2: 19.300941738924593 | M2: 73.21858197033089 | Q2: Registered - no adverse list match | R2: No | S2: No | U2: 2017-05-09 | V2: https://maharerait.maharashtra.gov.in/public/project/view/4 | W2: https://www.maharera.maharashtra.gov.in/projects-search-result?project_state=27&project_district=517&page=1 | X2: 2026-10-11 | Y2: Verified (official listing) | Z2: reg no, project name, promoter, district, taluka, pincode, last modified, detail URL | AA2: project address, registration date, original completion date, revised completion date | AB2: Cross-checked against 5 fully downloaded official lists (deregistered, 3 abeyance lists, NCLT) and the Revoked search (4/9 pages collected - revoked status may be under-reported)
A3: R000002 | B3: P51700000002 | C3: UNNATHI WOODS PHASE VII A | D3: UNNATHI ESTATES | E3: D01097 | G3: Thane | H3: 400615 | I3: Thane | J3: Mumbai MMR | K3: Thane district (incl. Thane, Navi Mumbai-Thane side, Mira-Bhayandar, Kalyan-Dombivli, Bhiwandi, Ulhasnagar, Ambernath) | L3: 19.268511 | M3: 72.97367 | Q3: Registered - no adverse list match | R3: No | S3: No | U3: 2018-04-12 | V3: https://maharerait.maharashtra.gov.in/public/project/view/3 | W3: https://www.maharera.maharashtra.gov.in/projects-search-result?project_state=27&project_district=517&page=1 | X3: 2026-10-11 | Y3: Verified (official listing) | Z3: reg no, project name, promoter, district, taluka, pincode, last modified, detail URL | AA3: project address, registration date, original completion date, revised completion date | AB3: Cross-checked against 5 fully downloaded official lists (deregistered, 3 abeyance lists, NCLT) and the Revoked search (4/9 pages collected - revoked status may be under-reported)
A4: R000003 | B4: P51700000006 | C4: THE PALMS | D4: METRO DEVELOPMENT | E4: D00576 | G4: Thane | H4: 400706 | I4: Thane | J4: Mumbai MMR | K4: Thane district (incl. Thane, Navi Mumbai-Thane side, Mira-Bhayandar, Kalyan-Dombivli, Bhiwandi, Ulhasnagar, Ambernath) | L4: 19.00971 | M4: 73.01719 | Q4: Registered - no adverse list match | R4: No | S4: No | U4: 2017-05-23 | V4: https://maharerait.maharashtra.gov.in/public/project/view/256 | W4: https://www.maharera.maharashtra.gov.in/projects-search-result?project_state=27&project_district=517&page=2 | X4: 2026-10-11 | Y4: Verified (official listing) | Z4: reg no, project name, promoter, district, taluka, pincode, last modified, detail URL | AA4: project address, registration date, original completion date, revised completion date | AB4: Cross-checked against 5 fully downloaded official lists (deregistered, 3 abeyance lists, NCLT) and the Revoked search (4/9 pages collected - revoked status may be under-reported)
A5: R000004 | B5: P51700000009 | C5: N G Silver Spring | D5: RNA Builders (NG) | E5: D00806 | G5: Thane | H5: 401107 | I5: Thane | J5: Mumbai MMR | K5: Thane district (incl. Thane, Navi Mumbai-Thane side, Mira-Bhayandar, Kalyan-Dombivli, Bhiwandi, Ulhasnagar, Ambernath) | L5: 19.2855196 | M5: 72.8692967 | Q5: Registered - no adverse list match | R5: No | S5: No | U5: 2017-05-23 | V5: https://maharerait.maharashtra.gov.in/public/project/view/825 | W5: https://www.maharera.maharashtra.gov.in/projects-search-result?project_state=27&project_district=517&page=2 | X5: 2026-10-11 | Y5: Verified (official listing) | Z5: reg no, project name, promoter, district, taluka, pincode, last modified, detail URL | AA5: project address, registration date, original completion date, revised completion date | AB5: Cross-checked against 5 fully downloaded official lists (deregistered, 3 abeyance lists, NCLT) and the Revoked search (4/9 pages collected - revoked status may be under-reported)
A6: R000005 | B6: P51700000038 | C6: THE WHITE VILLAS | D6: St. Angelo's VNCT Ventures Pvt. Ltd. | E6: D01024 | G6: Shahapur | H6: 420601 | I6: Thane | J6: Mumbai MMR | K6: Thane district (incl. Thane, Navi Mumbai-Thane side, Mira-Bhayandar, Kalyan-Dombivli, Bhiwandi, Ulhasnagar, Ambernath) | L6: 19.4559236 | M6: 73.3296037 | Q6: Registered - no adverse list match | R6: Yes | S6: No | U6: 2026-09-26 | V6: https://maharerait.maharashtra.gov.in/public/project/view/2491 | W6: https://www.maharera.maharashtra.gov.in/projects-search-result?project_state=27&project_district=517&page=4 | X6: 2026-10-11 | Y6: Verified (official listing) | Z6: reg no, project name, promoter, district, taluka, pincode, last modified, detail URL | AA6: project address, registration date, original completion date, revised completion date | AB6: Cross-checked against 5 fully downloaded official lists (deregistered, 3 abeyance lists, NCLT) and the Revoked search (4/9 pages collected - revoked status may be under-reported)
A7: R000006 | B7: P51700000053 | C7: GOLDSTAR DECENT HOMES | D7: GOLDSTAR SANKALP CONSTRUCTION | E7: D00305 | G7: Thane | H7: 401107 | I7: Thane | J7: Mumbai MMR | K7: Thane district (incl. Thane, Navi Mumbai-Thane side, Mira-Bhayandar, Kalyan-Dombivli, Bhiwandi, Ulhasnagar, Ambernath) | L7: 19.281762 | M7: 72.881768 | Q7: Registered - no adverse list match | R7: Yes | S7: No | U7: 2019-01-09 | V7: https://maharerait.maharashtra.gov.in/public/project/view/166 | W7: https://www.maharera.maharashtra.gov.in/projects-search-result?project_state=27&project_district=517&page=1 | X7: 2026-10-11 | Y7: Verified (official listing) | Z7: reg no, project name, promoter, district, taluka, pincode, last modified, detail URL | AA7: project address, registration date, original completion date, revised completion date | AB7: Cross-checked against 5 fully downloaded official lists (deregistered, 3 abeyance lists, NCLT) and the Revoked search (4/9 pages collected - revoked status may be under-reported)
A8: R000007 | B8: P51700000064 | C8: TULSI AAHAN | D8: RAJ GROUP | E8: D00777 | G8: Ambarnath | H8: 421503 | I8: Thane | J8: Mumbai MMR | K8: Thane district (incl. Thane, Navi Mumbai-Thane side, Mira-Bhayandar, Kalyan-Dombivli, Bhiwandi, Ulhasnagar, Ambernath) | L8: 19.1667854 | M8: 73.2367896 | Q8: Registered - no adverse list match | R8: No | S8: No | U8: 2017-06-22 | V8: https://maharerait.maharashtra.gov.in/public/project/view/1283 | W8: https://www.maharera.maharashtra.gov.in/projects-search-result?project_state=27&project_district=517&page=2 | X8: 2026-10-11 | Y8: Verified (official listing) | Z8: reg no, project name, promoter, district, taluka, pincode, last modified, detail URL | AA8: project address, registration date, original completion date, revised completion date | AB8: Cross-checked against 5 fully downloaded official lists (deregistered, 3 abeyance lists, NCLT) and the Revoked search (4/9 pages collected - revoked status may be under-reported)
A9: R000008 | B9: P51700000068 | C9: NG GRAND PLAZA PHASE I | D9: OM NAMAH SHIVAY DEVELOPERS PRIVATE LIMITED | E9: D00679 | G9: Thane | H9: 400701 | I9: Thane | J9: Mumbai MMR | K9: Thane district (incl. Thane, Navi Mumbai-Thane side, Mira-Bhayandar, Kalyan-Dombivli, Bhiwandi, Ulhasnagar, Ambernath) | L9: 19.118673 | M9: 72.992341 | Q9: Registered - no adverse list match | R9: No | S9: No | U9: 2017-06-22 | V9: https://maharerait.maharashtra.gov.in/public/project/view/2943 | W9: https://www.maharera.maharashtra.gov.in/projects-search-result?project_state=27&project_district=517&page=5 | X9: 2026-10-11 | Y9: Verified (official listing) | Z9: reg no, project name, promoter, district, taluka, pincode, last modified, detail URL | AA9: project address, registration date, original completion date, revised completion date | AB9: Cross-checked against 5 fully downloaded official lists (deregistered, 3 abeyance lists, NCLT) and the Revoked search (4/9 pages collected - revoked status may be under-reported)
A10: R000009 | B10: P51700000074 | C10: Juhi Serenity | D10: Vijaykumar Baldev Bajaj | E10: D01139 | G10: Thane | H10: 400701 | I10: Thane | J10: Mumbai MMR | K10: Thane district (incl. Thane, Navi Mumbai-Thane side, Mira-Bhayandar, Kalyan-Dombivli, Bhiwandi, Ulhasnagar, Ambernath) | L10: 19.118294 | M10: 72.996908 | Q10: Registered - no adverse list match | R10: No | S10: No | U10: 2017-06-28 | V10: https://maharerait.maharashtra.gov.in/public/project/view/3212 | W10: https://www.maharera.maharashtra.gov.in/projects-search-result?project_state=27&project_district=517&page=8 | X10: 2026-10-11 | Y10: Verified (official listing) | Z10: reg no, project name, promoter, district, taluka, pincode, last modified, detail URL | AA10: project address, registration date, original completion date, revised completion date | AB10: Cross-checked against 5 fully downloaded official lists (deregistered, 3 abeyance lists, NCLT) and the Revoked search (4/9 pages collected - revoked status may be under-reported)
A11: R000010 | B11: P51700000089 | C11: Eagleton | D11: ROMA BUILDERS PRIVATE LIMITED | E11: D00811 | G11: Thane | H11: 400607 | I11: Thane | J11: Mumbai MMR | K11: Thane district (incl. Thane, Navi Mumbai-Thane side, Mira-Bhayandar, Kalyan-Dombivli, Bhiwandi, Ulhasnagar, Ambernath) | L11: 19.24360352 | M11: 72.97722982 | Q11: Registered - no adverse list match | R11: No | S11: No | U11: 2017-06-29 | V11: https://maharerait.maharashtra.gov.in/public/project/view/3090 | W11: https://www.maharera.maharashtra.gov.in/projects-search-result?project_state=27&project_district=517&page=7 | X11: 2026-10-11 | Y11: Verified (official listing) | Z11: reg no, project name, promoter, district, taluka, pincode, last modified, detail URL | AA11: project address, registration date, original completion date, revised completion date | AB11: Cross-checked against 5 fully downloaded official lists (deregistered, 3 abeyance lists, NCLT) and the Revoked search (4/9 pages collected - revoked status may be under-reported)
A12: R000011 | B12: P51700000091 | C12: Hampton | D12: ROMA BUILDERS PRIVATE LIMITED | E12: D00811 | G12: Thane | H12: 400607 | I12: Thane | J12: Mumbai MMR | K12: Thane district (incl. Thane, Navi Mumbai-Thane side, Mira-Bhayandar, Kalyan-Dombivli, Bhiwandi, Ulhasnagar, Ambernath) | L12: 19.24360352 | M12: 72.97722982 | Q12: Registered - no adverse list match | R12: No | S12: No | U12: 2017-06-30 | V12: https://maharerait.maharashtra.gov.in/public/project/view/3293 | W12: https://www.maharera.maharashtra.gov.in/projects-search-result?project_state=27&project_district=517&page=8 | X12: 2026-10-11 | Y12: Verified (official listing) | Z12: reg no, project name, promoter, district, taluka, pincode, last modified, detail URL | AA12: project address, registration date, original completion date, revised completion date | AB12: Cross-checked against 5 fully downloaded official lists (deregistered, 3 abeyance lists, NCLT) and the Revoked search (4/9 pages collected - revoked status may be under-reported)
A13: R000012 | B13: P51700000095 | C13: Evergreen Heights | D13: Vijay Vasudev Wadhwa | E13: D01138 | G13: Thane | H13: 400605 | I13: Thane | J13: Mumbai MMR | K13: Thane district (incl. Thane, Navi Mumbai-Thane side, Mira-Bhayandar, Kalyan-Dombivli, Bhiwandi, Ulhasnagar, Ambernath) | L13: 19.206852 | M13: 73.014004 | Q13: Registered - no adverse list match | R13: No | S13: No | U13: 2017-06-30 | V13: https://maharerait.maharashtra.gov.in/public/project/view/228 | W13: https://www.maharera.maharashtra.gov.in/projects-search-result?project_state=27&project_district=517&page=1 | X13: 2026-10-11 | Y13: Verified (official listing) | Z13: reg no, project name, promoter, district, taluka, pincode, last modified, detail URL | AA13: project address, registration date, original completion date, revised completion date | AB13: Cross-checked against 5 fully downloaded official lists (deregistered, 3 abeyance lists, NCLT) and the Revoked search (4/9 pages collected - revoked status may be under-reported)
... A95: R000094 | B95: P51700000656 | C95: Panvelkar Homes - Phase II | D95: Om Sai Constructions | E95: D00681 | G95: Ambarnath | H95: 421501 | I95: Thane | J95: Mumbai MMR | K95: Thane district (incl. Thane, Navi Mumbai-Thane side, Mira-Bhayandar, Kalyan-Dombivli, Bhiwandi, Ulhasnagar, Ambernath) | L95: 19.208057 | M95: 73.205729 | Q95: Registered - no adverse list match | R95: No | S95: No | U95: 2019-03-05 | V95: https://maharerait.maharashtra.gov.in/public/project/view/5656 | W95: https://www.maharera.maharashtra.gov.in/projects-search-result?project_state=27&project_district=517&page=29 | X95: 2026-10-11 | Y95: Verified (official listing) | Z95: reg no, project name, promoter, district, taluka, pincode, last modified, detail URL | AA95: project address, registration date, original completion date, revised completion date | AB95: Cross-checked against 5 fully downloaded official lists (deregistered, 3 abeyance lists, NCLT) and the Revoked search (4/9 pages collected - revoked status may be under-reported)
A96: R000095 | B96: P51700000659 | C96: LODHA SPLENDORA - PLATINO - D | D96: MACROTECH DEVELOPERS LIMITED | E96: D00539 | G96: Thane | H96: 400607 | I96: Thane | J96: Mumbai MMR | K96: Thane district (incl. Thane, Navi Mumbai-Thane side, Mira-Bhayandar, Kalyan-Dombivli, Bhiwandi, Ulhasnagar, Ambernath) | L96: 19.2392834 | M96: 72.9873924 | Q96: Deregistered | R96: No | S96: Yes | T96: Deregistered: Planning authority: TMC | U96: 2018-04-06 | V96: https://maharerait.maharashtra.gov.in/public/project/view/2096 | W96: https://www.maharera.maharashtra.gov.in/projects-search-result?project_state=27&project_district=517&page=3 | X96: 2026-10-11 | Y96: Verified (official listing) | Z96: reg no, project name, promoter, district, taluka, pincode, last modified, detail URL | AA96: project address, registration date, original completion date, revised completion date | AB96: Cross-checked against 5 fully downloaded official lists (deregistered, 3 abeyance lists, NCLT) and the Revoked search (4/9 pages collected - revoked status may be under-reported)
A97: R000096 | B97: P51700000681 | C97: Courtyard - Ornella | D97: COURTYARD REAL ESTATE PRIVATE LIMITED | E97: D00179 | G97: Thane | H97: 400601 | I97: Thane | J97: Mumbai MMR | K97: Thane district (incl. Thane, Navi Mumbai-Thane side, Mira-Bhayandar, Kalyan-Dombivli, Bhiwandi, Ulhasnagar, Ambernath) | L97: 19.220122 | M97: 72.9637 | Q97: Registered - no adverse list match | R97: No | S97: No | U97: 2017-07-20 | V97: https://maharerait.maharashtra.gov.in/public/project/view/3236 | W97: https://www.maharera.maharashtra.gov.in/projects-search-result?project_state=27&project_district=517&page=8 | X97: 2026-10-11 | Y97: Verified (official listing) | Z97: reg no, project name, promoter, district, taluka, pincode, last modified, detail URL | AA97: project address, registration date, original completion date, revised completion date | AB97: Cross-checked against 5 fully downloaded official lists (deregistered, 3 abeyance lists, NCLT) and the Revoked search (4/9 pages collected - revoked status may be under-reported)
A98: R000097 | B98: P51700000686 | C98: MARATHON NEXTOWN EMERALD | D98: MARATHON ENER-GEN | E98: D00562 | G98: Thane | H98: 421201 | I98: Thane | J98: Mumbai MMR | K98: Thane district (incl. Thane, Navi Mumbai-Thane side, Mira-Bhayandar, Kalyan-Dombivli, Bhiwandi, Ulhasnagar, Ambernath) | L98: 19.161664 | M98: 73.055094 | Q98: Registered - no adverse list match | R98: Yes | S98: No | U98: 2020-06-13 | V98: https://maharerait.maharashtra.gov.in/public/project/view/4543 | W98: https://www.maharera.maharashtra.gov.in/projects-search-result?project_state=27&project_district=517&page=16 | X98: 2026-10-11 | Y98: Verified (official listing) | Z98: reg no, project name, promoter, district, taluka, pincode, last modified, detail URL | AA98: project address, registration date, original completion date, revised completion date | AB98: Cross-checked against 5 fully downloaded official lists (deregistered, 3 abeyance lists, NCLT) and the Revoked search (4/9 pages collected - revoked status may be under-reported)
A99: R000098 | B99: P51700000689 | C99: Rumahbali Phase 2 | D99: Puranik Builders Limited | E99: D00761 | G99: Thane | H99: 400615 | I99: Thane | J99: Mumbai MMR | K99: Thane district (incl. Thane, Navi Mumbai-Thane side, Mira-Bhayandar, Kalyan-Dombivli, Bhiwandi, Ulhasnagar, Ambernath) | L99: 19.271548 | M99: 72.9637728 | Q99: Registered - no adverse list match | R99: No | S99: No | U99: 2017-07-20 | V99: https://maharerait.maharashtra.gov.in/public/project/view/4016 | W99: https://www.maharera.maharashtra.gov.in/projects-search-result?project_state=27&project_district=517&page=11 | X99: 2026-10-11 | Y99: Verified (official listing) | Z99: reg no, project name, promoter, district, taluka, pincode, last modified, detail URL | AA99: project address, registration date, original completion date, revised completion date | AB99: Cross-checked against 5 fully downloaded official lists (deregistered, 3 abeyance lists, NCLT) and the Revoked search (4/9 pages collected - revoked status may be under-reported)
A100: R000099 | B100: P51700000696 | C100: PALAVA URBANO G AND H | D100: Palava Dwellers Private Limited | E100: D00697 | G100: Kalyan | H100: 421202 | I100: Thane | J100: Mumbai MMR | K100: Thane district (incl. Thane, Navi Mumbai-Thane side, Mira-Bhayandar, Kalyan-Dombivli, Bhiwandi, Ulhasnagar, Ambernath) | L100: 19.1714522 | M100: 73.1190742 | Q100: Registered - no adverse list match | R100: No | S100: No | U100: 2018-09-28 | V100: https://maharerait.maharashtra.gov.in/public/project/view/4275 | W100: https://www.maharera.maharashtra.gov.in/projects-search-result?project_state=27&project_district=517&page=14 | X100: 2026-10-11 | Y100: Verified (official listing) | Z100: reg no, project name, promoter, district, taluka, pincode, last modified, detail URL | AA100: project address, registration date, original completion date, revised completion date | AB100: Cross-checked against 5 fully downloaded official lists (deregistered, 3 abeyance lists, NCLT) and the Revoked search (4/9 pages collected - revoked status may be under-reported)
A101: R000100 | B101: P51700000704 | C101: Amanda Shopping | D101: HIRANANDANI PROPERTIES PRIVATE LIMITED | E101: D00352 | G101: Thane | H101: 400610 | I101: Thane | J101: Mumbai MMR | K101: Thane district (incl. Thane, Navi Mumbai-Thane side, Mira-Bhayandar, Kalyan-Dombivli, Bhiwandi, Ulhasnagar, Ambernath) | L101: 19.22728624110684 | M101: 72.9735051871719 | Q101: Registered - no adverse list match | R101: No | S101: No | U101: 2017-07-20 | V101: https://maharerait.maharashtra.gov.in/public/project/view/5677 | W101: https://www.maharera.maharashtra.gov.in/projects-search-result?project_state=27&project_district=517&page=29 | X101: 2026-10-11 | Y101: Verified (official listing) | Z101: reg no, project name, promoter, district, taluka, pincode, last modified, detail URL | AA101: project address, registration date, original completion date, revised completion date | AB101: Cross-checked against 5 fully downloaded official lists (deregistered, 3 abeyance lists, NCLT) and the Revoked search (4/9 pages collected - revoked status may be under-reported)
A102: R000101 | B102: P51700000714 | C102: Courtyard - Onyx | D102: COURTYARD REAL ESTATE PRIVATE LIMITED | E102: D00179 | G102: Thane | H102: 400601 | I102: Thane | J102: Mumbai MMR | K102: Thane district (incl. Thane, Navi Mumbai-Thane side, Mira-Bhayandar, Kalyan-Dombivli, Bhiwandi, Ulhasnagar, Ambernath) | L102: 19.220892 | M102: 72.96492 | Q102: Registered - no adverse list match | R102: No | S102: No | U102: 2017-07-20 | V102: https://maharerait.maharashtra.gov.in/public/project/view/3275 | W102: https://www.maharera.maharashtra.gov.in/projects-search-result?project_state=27&project_district=517&page=8 | X102: 2026-10-11 | Y102: Verified (official listing) | Z102: reg no, project name, promoter, district, taluka, pincode, last modified, detail URL | AA102: project address, registration date, original completion date, revised completion date | AB102: Cross-checked against 5 fully downloaded official lists (deregistered, 3 abeyance lists, NCLT) and the Revoked search (4/9 pages collected - revoked status may be under-reported)
A103: R000102 | B103: P51700000725 | C103: SARVODAY AANAND | D103: OM SAI LAND DEVELOPERS | E103: D00682 | G103: Kalyan | H103: 421202 | I103: Thane | J103: Mumbai MMR | K103: Thane district (incl. Thane, Navi Mumbai-Thane side, Mira-Bhayandar, Kalyan-Dombivli, Bhiwandi, Ulhasnagar, Ambernath) | L103: 19.221922 | M103: 73.082294 | Q103: Registered - no adverse list match | R103: Yes | S103: No | U103: 2026-10-06 | V103: https://maharerait.maharashtra.gov.in/public/project/view/5117 | W103: https://www.maharera.maharashtra.gov.in/projects-search-result?project_state=27&project_district=517&page=23 | X103: 2026-10-11 | Y103: Verified (official listing) | Z103: reg no, project name, promoter, district, taluka, pincode, last modified, detail URL | AA103: project address, registration date, original completion date, revised completion date | AB103: Cross-checked against 5 fully downloaded official lists (deregistered, 3 abeyance lists, NCLT) and the Revoked search (4/9 pages collected - revoked status may be under-reported)
A104: R000103 | B104: P51700000732 | C104: Immensa D | D104: Agile Real Estate Pvt. Ltd. | E104: D00038 | G104: Thane | H104: 400607 | I104: Thane | J104: Mumbai MMR | K104: Thane district (incl. Thane, Navi Mumbai-Thane side, Mira-Bhayandar, Kalyan-Dombivli, Bhiwandi, Ulhasnagar, Ambernath) | L104: 19.2317808758669 | M104: 72.99011107794036 | Q104: Registered - no adverse list match | R104: No | S104: No | U104: 2024-05-20 | V104: https://maharerait.maharashtra.gov.in/public/project/view/5415 | W104: https://www.maharera.maharashtra.gov.in/projects-search-result?project_state=27&project_district=517&page=27 | X104: 2026-10-11 | Y104: Verified (official listing) | Z104: reg no, project name, promoter, district, taluka, pincode, last modified, detail URL | AA104: project address, registration date, original completion date, revised completion date | AB104: Cross-checked against 5 fully downloaded official lists (deregistered, 3 abeyance lists, NCLT) and the Revoked search (4/9 pages collected - revoked status may be under-reported)
A105: R000104 | B105: P51700000734 | C105: VASANT FIONA | D105: Sheth Developers Private Limited | E105: D00917 | G105: Thane | H105: 400601 | I105: Thane | J105: Mumbai MMR | K105: Thane district (incl. Thane, Navi Mumbai-Thane side, Mira-Bhayandar, Kalyan-Dombivli, Bhiwandi, Ulhasnagar, Ambernath) | L105: 19.2010502 | M105: 72.9785353 | Q105: Registered - no adverse list match | R105: No | S105: No | U105: 2017-07-23 | V105: https://maharerait.maharashtra.gov.in/public/project/view/2723 | W105: https://www.maharera.maharashtra.gov.in/projects-search-result?project_state=27&project_district=517&page=5 | X105: 2026-10-11 | Y105: Verified (official listing) | Z105: reg no, project name, promoter, district, taluka, pincode, last modified, detail URL | AA105: project address, registration date, original completion date, revised completion date | AB105: Cross-checked against 5 fully downloaded official lists (deregistered, 3 abeyance lists, NCLT) and the Revoked search (4/9 pages collected - revoked status may be under-reported)
A106: R000105 | B106: P51700000736 | C106: SKY VILLAS WING A1 AND WING A2 | D106: VERTEX NEWTON PROJECTS PRIVATE LIMITED | E106: D01128 | G106: Kalyan | H106: 421301 | I106: Thane | J106: Mumbai MMR | K106: Thane district (incl. Thane, Navi Mumbai-Thane side, Mira-Bhayandar, Kalyan-Dombivli, Bhiwandi, Ulhasnagar, Ambernath) | L106: 19.2527132 | M106: 73.1290596 | Q106: Registered - no adverse list match | R106: No | S106: No | U106: 2017-07-23 | V106: https://maharerait.maharashtra.gov.in/public/project/view/6172 | W106: https://www.maharera.maharashtra.gov.in/projects-search-result?project_state=27&project_district=517&page=34 | X106: 2026-10-11 | Y106: Verified (official listing) | Z106: reg no, project name, promoter, district, taluka, pincode, last modified, detail URL | AA106: project address, registration date, original completion date, revised completion date | AB106: Cross-checked against 5 fully downloaded official lists (deregistered, 3 abeyance lists, NCLT) and the Revoked search (4/9 pages collected - revoked status may be under-reported)
A107: R000106 | B107: P51700000743 | C107: PRAMUKH SADAN | D107: SAHAJANAND DEVELOPERS | E107: D00845 | G107: Ambarnath | H107: 421501 | I107: Thane | J107: Mumbai MMR | K107: Thane district (incl. Thane, Navi Mumbai-Thane side, Mira-Bhayandar, Kalyan-Dombivli, Bhiwandi, Ulhasnagar, Ambernath) | L107: 19.2007023 | M107: 73.1880618 | Q107: Registered - no adverse list match | R107: No | S107: No | U107: 2017-07-23 | V107: https://maharerait.maharashtra.gov.in/public/project/view/3564 | W107: https://www.maharera.maharashtra.gov.in/projects-search-result?project_state=27&project_district=517&page=9 | X107: 2026-10-11 | Y107: Verified (official listing) | Z107: reg no, project name, promoter, district, taluka, pincode, last modified, detail URL | AA107: project address, registration date, original completion date, revised completion date | AB107: Cross-checked against 5 fully downloaded official lists (deregistered, 3 abeyance lists, NCLT) and the Revoked search (4/9 pages collected - revoked status may be under-reported)
A108: R000107 | B108: P51700000745 | C108: PATEL RESIDENCY NX | D108: NAVNIRMAN DEVELOPERS | E108: D00633 | G108: Ambarnath | H108: 421501 | I108: Thane | J108: Mumbai MMR | K108: Thane district (incl. Thane, Navi Mumbai-Thane side, Mira-Bhayandar, Kalyan-Dombivli, Bhiwandi, Ulhasnagar, Ambernath) | L108: 19.2007023 | M108: 73.1880618 | Q108: Registered - no adverse list match | R108: No | S108: No | U108: 2017-07-23 | V108: https://maharerait.maharashtra.gov.in/public/project/view/3967 | W108: https://www.maharera.maharashtra.gov.in/projects-search-result?project_state=27&project_district=517&page=11 | X108: 2026-10-11 | Y108: Verified (official listing) | Z108: reg no, project name, promoter, district, taluka, pincode, last modified, detail URL | AA108: project address, registration date, original completion date, revised completion date | AB108: Cross-checked against 5 fully downloaded official lists (deregistered, 3 abeyance lists, NCLT) and the Revoked search (4/9 pages collected - revoked status may be under-reported)
... A197: R000196 | B197: P51700001561 | C197: MEERA PARK ROYALE | D197: SARASWATI BUILDCON | E197: D00887 | G197: Ambarnath | H197: 421501 | I197: Thane | J197: Mumbai MMR | K197: Thane district (incl. Thane, Navi Mumbai-Thane side, Mira-Bhayandar, Kalyan-Dombivli, Bhiwandi, Ulhasnagar, Ambernath) | L197: 19.192824968749388 | M197: 73.19552023554729 | Q197: Registered - no adverse list match | R197: Yes | S197: No | U197: 2021-09-09 | V197: https://maharerait.maharashtra.gov.in/public/project/view/6730 | W197: https://www.maharera.maharashtra.gov.in/projects-search-result?project_state=27&project_district=517&page=40 | X197: 2026-10-11 | Y197: Verified (official listing) | Z197: reg no, project name, promoter, district, taluka, pincode, last modified, detail URL | AA197: project address, registration date, original completion date, revised completion date | AB197: Cross-checked against 5 fully downloaded official lists (deregistered, 3 abeyance lists, NCLT) and the Revoked search (4/9 pages collected - revoked status may be under-reported)
A198: R000197 | B198: P51700001566 | C198: SAI WORLD RETREAT | D198: Paradise Leisure Homes | E198: D00704 | G198: Ulhasnagar | H198: 421002 | I198: Thane | J198: Mumbai MMR | K198: Thane district (incl. Thane, Navi Mumbai-Thane side, Mira-Bhayandar, Kalyan-Dombivli, Bhiwandi, Ulhasnagar, Ambernath) | L198: 18.765335 | M198: 73.436267 | Q198: Deregistered | R198: No | S198: Yes | T198: Deregistered: Planning authority: PMRDA | U198: 2017-07-28 | V198: https://maharerait.maharashtra.gov.in/public/project/view/4872 | W198: https://www.maharera.maharashtra.gov.in/projects-search-result?project_state=27&project_district=517&page=20 | X198: 2026-10-11 | Y198: Verified (official listing) | Z198: reg no, project name, promoter, district, taluka, pincode, last modified, detail URL | AA198: project address, registration date, original completion date, revised completion date | AB198: Cross-checked against 5 fully downloaded official lists (deregistered, 3 abeyance lists, NCLT) and the Revoked search (4/9 pages collected - revoked status may be under-reported)
A199: R000198 | B199: P51700001570 | C199: GOPAL KRISHNA | D199: SONAL DEV-CON PVT LTD | E199: D01011 | G199: Thane | H199: 400614 | I199: Thane | J199: Mumbai MMR | K199: Thane district (incl. Thane, Navi Mumbai-Thane side, Mira-Bhayandar, Kalyan-Dombivli, Bhiwandi, Ulhasnagar, Ambernath) | L199: 19.02296510646092 | M199: 73.03490847519072 | Q199: Registered - no adverse list match | R199: Yes | S199: No | U199: 2026-08-20 | V199: https://maharerait.maharashtra.gov.in/public/project/view/7058 | W199: https://www.maharera.maharashtra.gov.in/projects-search-result?project_state=27&project_district=517&page=43 | X199: 2026-10-11 | Y199: Verified (official listing) | Z199: reg no, project name, promoter, district, taluka, pincode, last modified, detail URL | AA199: project address, registration date, original completion date, revised completion date | AB199: Cross-checked against 5 fully downloaded official lists (deregistered, 3 abeyance lists, NCLT) and the Revoked search (4/9 pages collected - revoked status may be under-reported)
A200: R000199 | B200: P51700001574 | C200: MAITHILI PRIDE | D200: MAITHILI KALPVRUKSH PRIVATE LIMITED | E200: D00545 | G200: Thane | H200: 400606 | I200: Thane | J200: Mumbai MMR | K200: Thane district (incl. Thane, Navi Mumbai-Thane side, Mira-Bhayandar, Kalyan-Dombivli, Bhiwandi, Ulhasnagar, Ambernath) | L200: 19.212512 | M200: 72.960472 | Q200: Registered - no adverse list match | R200: Yes | S200: No | U200: 2021-09-09 | V200: https://maharerait.maharashtra.gov.in/public/project/view/6586 | W200: https://www.maharera.maharashtra.gov.in/projects-search-result?project_state=27&project_district=517&page=38 | X200: 2026-10-11 | Y200: Verified (official listing) | Z200: reg no, project name, promoter, district, taluka, pincode, last modified, detail URL | AA200: project address, registration date, original completion date, revised completion date | AB200: Cross-checked against 5 fully downloaded official lists (deregistered, 3 abeyance lists, NCLT) and the Revoked search (4/9 pages collected - revoked status may be under-reported)
A201: R000200 | B201: P51700001595 | C201: SHREE SHASHWAT BUILDING NO 19 | D201: Shashwat Developers | E201: D00913 | G201: Thane | H201: 401107 | I201: Thane | J201: Mumbai MMR | K201: Thane district (incl. Thane, Navi Mumbai-Thane side, Mira-Bhayandar, Kalyan-Dombivli, Bhiwandi, Ulhasnagar, Ambernath) | L201: 19.2763286 | M201: 72.8759478 | Q201: Registered - no adverse list match | R201: Yes | S201: No | U201: 2021-09-09 | V201: https://maharerait.maharashtra.gov.in/public/project/view/5792 | W201: https://www.maharera.maharashtra.gov.in/projects-search-result?project_state=27&project_district=517&page=30 | X201: 2026-10-11 | Y201: Verified (official listing) | Z201: reg no, project name, promoter, district, taluka, pincode, last modified, detail URL | AA201: project address, registration date, original completion date, revised completion date | AB201: Cross-checked against 5 fully downloaded official lists (deregistered, 3 abeyance lists, NCLT) and the Revoked search (4/9 pages collected - revoked status may be under-reported)
A202: R000201 | B202: P51700001597 | C202: SIDDHICITY | D202: Siddhitech Homes Private Limited | E202: D00990 | G202: Ambarnath | H202: 421503 | I202: Thane | J202: Mumbai MMR | K202: Thane district (incl. Thane, Navi Mumbai-Thane side, Mira-Bhayandar, Kalyan-Dombivli, Bhiwandi, Ulhasnagar, Ambernath) | L202: 19.142212 | M202: 73.246316 | Q202: Registered - no adverse list match | R202: Yes | S202: No | U202: 2018-06-25 | V202: https://maharerait.maharashtra.gov.in/public/project/view/6015 | W202: https://www.maharera.maharashtra.gov.in/projects-search-result?project_state=27&project_district=517&page=33 | X202: 2026-10-11 | Y202: Verified (official listing) | Z202: reg no, project name, promoter, district, taluka, pincode, last modified, detail URL | AA202: project address, registration date, original completion date, revised completion date | AB202: Cross-checked against 5 fully downloaded official lists (deregistered, 3 abeyance lists, NCLT) and the Revoked search (4/9 pages collected - revoked status may be under-reported)
